Traceback (most recent call last):
  File "/opt/hostedtoolcache/Python/3.12.11/x64/lib/python3.12/site-packages/jupyter_core/utils/__init__.py", line 154, in wrapped
    asyncio.get_running_loop()
RuntimeError: no running event loop

During handling of the above exception, another exception occurred:

Traceback (most recent call last):
  File "/opt/hostedtoolcache/Python/3.12.11/x64/lib/python3.12/site-packages/jupyter_cache/executors/utils.py", line 58, in single_nb_execution
    executenb(
  File "/opt/hostedtoolcache/Python/3.12.11/x64/lib/python3.12/site-packages/nbclient/client.py", line 1319, in execute
    return NotebookClient(nb=nb, resources=resources, km=km, **kwargs).execute()
           ^^^^^^^^^^^^^^^^^^^^^^^^^^^^^^^^^^^^^^^^^^^^^^^^^^^^^^^^^^^^^^^^^^^^^
  File "/opt/hostedtoolcache/Python/3.12.11/x64/lib/python3.12/site-packages/jupyter_core/utils/__init__.py", line 158, in wrapped
    return loop.run_until_complete(inner)
           ^^^^^^^^^^^^^^^^^^^^^^^^^^^^^^
  File "/opt/hostedtoolcache/Python/3.12.11/x64/lib/python3.12/asyncio/base_events.py", line 691, in run_until_complete
    return future.result()
           ^^^^^^^^^^^^^^^
  File "/opt/hostedtoolcache/Python/3.12.11/x64/lib/python3.12/site-packages/nbclient/client.py", line 709, in async_execute
    await self.async_execute_cell(
  File "/opt/hostedtoolcache/Python/3.12.11/x64/lib/python3.12/site-packages/nbclient/client.py", line 1062, in async_execute_cell
    await self._check_raise_for_error(cell, cell_index, exec_reply)
  File "/opt/hostedtoolcache/Python/3.12.11/x64/lib/python3.12/site-packages/nbclient/client.py", line 918, in _check_raise_for_error
    raise CellExecutionError.from_cell_and_msg(cell, exec_reply_content)
nbclient.exceptions.CellExecutionError: An error occurred while executing the following cell:
------------------
from jupytercards import display_flashcards
display_flashcards('./material/cards_1.json', front_colors=["beige"], back_colors=["cyan"], text_colors=["black"])
------------------


[31m---------------------------------------------------------------------------[39m
[31mFileNotFoundError[39m                         Traceback (most recent call last)
[36mCell[39m[36m [39m[32mIn[1][39m[32m, line 2[39m
[32m      1[39m [38;5;28;01mfrom[39;00m[38;5;250m [39m[34;01mjupytercards[39;00m[38;5;250m [39m[38;5;28;01mimport[39;00m display_flashcards
[32m----> [39m[32m2[39m [43mdisplay_flashcards[49m[43m([49m[33;43m'[39;49m[33;43m./material/cards_1.json[39;49m[33;43m'[39;49m[43m,[49m[43m [49m[43mfront_colors[49m[43m=[49m[43m[[49m[33;43m"[39;49m[33;43mbeige[39;49m[33;43m"[39;49m[43m][49m[43m,[49m[43m [49m[43mback_colors[49m[43m=[49m[43m[[49m[33;43m"[39;49m[33;43mcyan[39;49m[33;43m"[39;49m[43m][49m[43m,[49m[43m [49m[43mtext_colors[49m[43m=[49m[43m[[49m[33;43m"[39;49m[33;43mblack[39;49m[33;43m"[39;49m[43m][49m[43m)[49m

[36mFile [39m[32m/opt/hostedtoolcache/Python/3.12.11/x64/lib/python3.12/site-packages/jupytercards/dynamic.py:275[39m, in [36mdisplay_flashcards[39m[34m(ref, keyControl, grabFocus, shuffle_cards, front_colors, back_colors, text_colors, title, subject, topics, known_widgets, local_storage)[39m
[32m    272[39m     all_cards = json.loads(json_data)
[32m    273[39m [38;5;28;01melse[39;00m:
[32m    274[39m     [38;5;66;03m#print("File detected")[39;00m
[32m--> [39m[32m275[39m     [38;5;28;01mwith[39;00m [38;5;28;43mopen[39;49m[43m([49m[43mref[49m[43m)[49m [38;5;28;01mas[39;00m file:
[32m    276[39m         [38;5;28;01mfor[39;00m line [38;5;129;01min[39;00m file:
[32m    277[39m             json_data += line

[31mFileNotFoundError[39m: [Errno 2] No such file or directory: './material/cards_1.json'

